E.......
======================================================================
ERROR: test_delete_nonexistent (__main__.TestAssignment2.test_delete_nonexistent)
----------------------------------------------------------------------
Traceback (most recent call last):
  File "/Users/amin/.pyenv/versions/playground/lib/python3.11/site-packages/urllib3/connectionpool.py", line 703, in urlopen
    httplib_response = self._make_request(
                       ^^^^^^^^^^^^^^^^^^^
  File "/Users/amin/.pyenv/versions/playground/lib/python3.11/site-packages/urllib3/connectionpool.py", line 449, in _make_request
    six.raise_from(e, None)
  File "<string>", line 3, in raise_from
  File "/Users/amin/.pyenv/versions/playground/lib/python3.11/site-packages/urllib3/connectionpool.py", line 444, in _make_request
    httplib_response = conn.getresponse()
                       ^^^^^^^^^^^^^^^^^^
  File "/Users/amin/.pyenv/versions/3.11.1/lib/python3.11/http/client.py", line 1374, in getresponse
    response.begin()
  File "/Users/amin/.pyenv/versions/3.11.1/lib/python3.11/http/client.py", line 318, in begin
    version, status, reason = self._read_status()
                              ^^^^^^^^^^^^^^^^^^^
  File "/Users/amin/.pyenv/versions/3.11.1/lib/python3.11/http/client.py", line 287, in _read_status
    raise RemoteDisconnected("Remote end closed connection without"
http.client.RemoteDisconnected: Remote end closed connection without response

During handling of the above exception, another exception occurred:

Traceback (most recent call last):
  File "/Users/amin/.pyenv/versions/playground/lib/python3.11/site-packages/requests/adapters.py", line 489, in send
    resp = conn.urlopen(
           ^^^^^^^^^^^^^
  File "/Users/amin/.pyenv/versions/playground/lib/python3.11/site-packages/urllib3/connectionpool.py", line 787, in urlopen
    retries = retries.increment(
              ^^^^^^^^^^^^^^^^^^
  File "/Users/amin/.pyenv/versions/playground/lib/python3.11/site-packages/urllib3/util/retry.py", line 550, in increment
    raise six.reraise(type(error), error, _stacktrace)
          ^^^^^^^^^^^^^^^^^^^^^^^^^^^^^^^^^^^^^^^^^^^^
  File "/Users/amin/.pyenv/versions/playground/lib/python3.11/site-packages/urllib3/packages/six.py", line 769, in reraise
    raise value.with_traceback(tb)
  File "/Users/amin/.pyenv/versions/playground/lib/python3.11/site-packages/urllib3/connectionpool.py", line 703, in urlopen
    httplib_response = self._make_request(
                       ^^^^^^^^^^^^^^^^^^^
  File "/Users/amin/.pyenv/versions/playground/lib/python3.11/site-packages/urllib3/connectionpool.py", line 449, in _make_request
    six.raise_from(e, None)
  File "<string>", line 3, in raise_from
  File "/Users/amin/.pyenv/versions/playground/lib/python3.11/site-packages/urllib3/connectionpool.py", line 444, in _make_request
    httplib_response = conn.getresponse()
                       ^^^^^^^^^^^^^^^^^^
  File "/Users/amin/.pyenv/versions/3.11.1/lib/python3.11/http/client.py", line 1374, in getresponse
    response.begin()
  File "/Users/amin/.pyenv/versions/3.11.1/lib/python3.11/http/client.py", line 318, in begin
    version, status, reason = self._read_status()
                              ^^^^^^^^^^^^^^^^^^^
  File "/Users/amin/.pyenv/versions/3.11.1/lib/python3.11/http/client.py", line 287, in _read_status
    raise RemoteDisconnected("Remote end closed connection without"
urllib3.exceptions.ProtocolError: ('Connection aborted.', RemoteDisconnected('Remote end closed connection without response'))

During handling of the above exception, another exception occurred:

Traceback (most recent call last):
  File "/Users/amin/Downloads/CSE 138/Assignment_2/grading/test_assignment2_follower-error.py", line 41, in setUp
    delete(k)
  File "/Users/amin/Downloads/CSE 138/Assignment_2/grading/test_assignment2_follower-error.py", line 33, in delete
    return requests.delete(url, json={'key': key})
           ^^^^^^^^^^^^^^^^^^^^^^^^^^^^^^^^^^^^^^^
  File "/Users/amin/.pyenv/versions/playground/lib/python3.11/site-packages/requests/api.py", line 157, in delete
    return request("delete", url, **kwargs)
           ^^^^^^^^^^^^^^^^^^^^^^^^^^^^^^^^
  File "/Users/amin/.pyenv/versions/playground/lib/python3.11/site-packages/requests/api.py", line 59, in request
    return session.request(method=method, url=url, **kwargs)
           ^^^^^^^^^^^^^^^^^^^^^^^^^^^^^^^^^^^^^^^^^^^^^^^^^
  File "/Users/amin/.pyenv/versions/playground/lib/python3.11/site-packages/requests/sessions.py", line 587, in request
    resp = self.send(prep, **send_kwargs)
           ^^^^^^^^^^^^^^^^^^^^^^^^^^^^^^
  File "/Users/amin/.pyenv/versions/playground/lib/python3.11/site-packages/requests/sessions.py", line 701, in send
    r = adapter.send(request, **kwargs)
        ^^^^^^^^^^^^^^^^^^^^^^^^^^^^^^^
  File "/Users/amin/.pyenv/versions/playground/lib/python3.11/site-packages/requests/adapters.py", line 547, in send
    raise ConnectionError(err, request=request)
requests.exceptions.ConnectionError: ('Connection aborted.', RemoteDisconnected('Remote end closed connection without response'))

----------------------------------------------------------------------
Ran 8 tests in 187.601s

FAILED (errors=1)
